Workbook

Sheet Tushum va Harajatlar
A2: No | B2: No ID | C2: sana | D2: Proeyekt nomi | E2: Tushum nomi | F2: Harajat nomi | G2: Buyurtmachi | H2: Mas'ul | I2: kimga tolangani | J2: Hujjat ID | K2: Shartnoma (USD) | L2: Shartnoma (UZS) | M2: Summa (USD) | N2: Summa (UZS) | O2: Qoldiq (USD) | P2: Qoldiq (UZS) | Q2: To'lov turi | R2: Kategoriya | S2: Muddat | T2: Status | U2: sharx
A3: 1 | B3: PRJ-001 | C3: 44750 | D3: Toshkent City Tower | E3: Toshkent City Tower — avans 40% | G3: Toshkent Invest LLC | H3: Aliyev Sardor | I3: Karimov Sherzod | J3: SH-001 | K3: =IF(L3=0,0,L3/LOOKUP(C3,Settings!$F$5:$F$20,Settings!$G$5:$G$20)) -> 78341.014 | L3: 850000000 | M3: =IF(N3=0,0,N3/LOOKUP(C3,Settings!$F$5:$F$20,Settings!$G$5:$G$20)) -> 31336.406 | N3: 340000000 | O3: =K3-M3 -> 47004.608 | P3: =L3-N3 -> 510000000 | Q3: Bank o'tkazmasi | R3: Tushum | S3: 44780 | T3: To'langan | U3: Avans 40%
A4: 2 | B4: PRJ-002 | C4: 44786 | D4: Samarqand Hotel | E4: Samarqand Hotel — avans 40% | G4: Silk Road Hotels | H4: Karimov Davron | I4: Muxammadiyev Baxtiyor | J4: SH-002 | K4: =IF(L4=0,0,L4/LOOKUP(C4,Settings!$F$5:$F$20,Settings!$G$5:$G$20)) -> 110599.08 | L4: 1200000000 | M4: =IF(N4=0,0,N4/LOOKUP(C4,Settings!$F$5:$F$20,Settings!$G$5:$G$20)) -> 44239.631 | N4: 480000000 | O4: =K4-M4 -> 66359.447 | P4: =L4-N4 -> 720000000 | Q4: Bank o'tkazmasi | R4: Tushum | S4: 44816 | T4: To'langan | U4: Avans 40%
A5: 3 | B5: PRJ-001 | C5: 44796 | D5: Toshkent City Tower | E5: Toshkent City Tower — 2-to'lov 30% | G5: Toshkent Invest LLC | H5: Aliyev Sardor | I5: Karimov Sherzod | J5: SH-001 | K5: =IF(L5=0,0,L5/LOOKUP(C5,Settings!$F$5:$F$20,Settings!$G$5:$G$20)) -> 78341.014 | L5: 850000000 | M5: =IF(N5=0,0,N5/LOOKUP(C5,Settings!$F$5:$F$20,Settings!$G$5:$G$20)) -> 23502.304 | N5: 255000000 | O5: =K5-M5 -> 54838.71 | P5: =L5-N5 -> 595000000 | Q5: Bank o'tkazmasi | R5: Tushum | S5: 44811 | T5: To'langan | U5: 2-bosqich 30%
A6: 4 | B6: PRJ-003 | C6: 44843 | D6: Buxoro Madaniyat Markazi | E6: Buxoro Madaniyat Markazi — avans 40% | G6: Buxoro Hokimligi | H6: Rahimov Jasur | I6: Xasanov Nodir | J6: SH-003 | K6: =IF(L6=0,0,L6/LOOKUP(C6,Settings!$F$5:$F$20,Settings!$G$5:$G$20)) -> 58823.529 | L6: 650000000 | M6: =IF(N6=0,0,N6/LOOKUP(C6,Settings!$F$5:$F$20,Settings!$G$5:$G$20)) -> 23529.412 | N6: 260000000 | O6: =K6-M6 -> 35294.118 | P6: =L6-N6 -> 390000000 | Q6: Bank o'tkazmasi | R6: Tushum | S6: 44873 | T6: To'langan | U6: Avans 40%
A7: 5 | B7: PRJ-002 | C7: 44846 | D7: Samarqand Hotel | E7: Samarqand Hotel — 2-to'lov 30% | G7: Silk Road Hotels | H7: Karimov Davron | I7: Muxammadiyev Baxtiyor | J7: SH-002 | K7: =IF(L7=0,0,L7/LOOKUP(C7,Settings!$F$5:$F$20,Settings!$G$5:$G$20)) -> 108597.29 | L7: 1200000000 | M7: =IF(N7=0,0,N7/LOOKUP(C7,Settings!$F$5:$F$20,Settings!$G$5:$G$20)) -> 32579.186 | N7: 360000000 | O7: =K7-M7 -> 76018.1 | P7: =L7-N7 -> 840000000 | Q7: Bank o'tkazmasi | R7: Tushum | S7: 44861 | T7: To'langan | U7: 2-bosqich 30%
A8: 6 | B8: PRJ-003 | C8: 44894 | D8: Buxoro Madaniyat Markazi | E8: Buxoro Madaniyat Markazi — 2-to'lov 30% | G8: Buxoro Hokimligi | H8: Rahimov Jasur | I8: Xasanov Nodir | J8: SH-003 | K8: =IF(L8=0,0,L8/LOOKUP(C8,Settings!$F$5:$F$20,Settings!$G$5:$G$20)) -> 58823.529 | L8: 650000000 | M8: =IF(N8=0,0,N8/LOOKUP(C8,Settings!$F$5:$F$20,Settings!$G$5:$G$20)) -> 17647.059 | N8: 195000000 | O8: =K8-M8 -> 41176.471 | P8: =L8-N8 -> 455000000 | Q8: Bank o'tkazmasi | R8: Tushum | S8: 44909 | T8: To'langan | U8: 2-bosqich 30%
A9: 7 | B9: PRJ-004 | C9: 44902 | D9: Chilonzor Turar-joy | E9: Chilonzor Turar-joy — avans 40% | G9: Ideal House LLC | H9: Aliyev Sardor | I9: Abdullayev Ravshan | J9: SH-004 | K9: =IF(L9=0,0,L9/LOOKUP(C9,Settings!$F$5:$F$20,Settings!$G$5:$G$20)) -> 38009.05 | L9: 420000000 | M9: =IF(N9=0,0,N9/LOOKUP(C9,Settings!$F$5:$F$20,Settings!$G$5:$G$20)) -> 15203.62 | N9: 168000000 | O9: =K9-M9 -> 22805.43 | P9: =L9-N9 -> 252000000 | Q9: Bank o'tkazmasi | R9: Tushum | S9: 44932 | T9: To'langan | U9: Avans 40%
A10: 8 | B10: PRJ-001 | C10: 44903 | D10: Toshkent City Tower | E10: Toshkent City Tower — yakuniy 30% | G10: Toshkent Invest LLC | H10: Aliyev Sardor | I10: Karimov Sherzod | J10: SH-001 | K10: =IF(L10=0,0,L10/LOOKUP(C10,Settings!$F$5:$F$20,Settings!$G$5:$G$20)) -> 76923.077 | L10: 850000000 | M10: =IF(N10=0,0,N10/LOOKUP(C10,Settings!$F$5:$F$20,Settings!$G$5:$G$20)) -> 23076.923 | N10: 255000000 | O10: =K10-M10 -> 53846.154 | P10: =L10-N10 -> 595000000 | Q10: Bank o'tkazmasi | R10: Tushum | S10: 44933 | T10: To'langan | U10: Yakuniy 30%
A11: 9 | B11: PRJ-002 | C11: 44920 | D11: Samarqand Hotel | E11: Samarqand Hotel — yakuniy 30% | G11: Silk Road Hotels | H11: Karimov Davron | I11: Muxammadiyev Baxtiyor | J11: SH-002 | K11: =IF(L11=0,0,L11/LOOKUP(C11,Settings!$F$5:$F$20,Settings!$G$5:$G$20)) -> 108597.29 | L11: 1200000000 | M11: =IF(N11=0,0,N11/LOOKUP(C11,Settings!$F$5:$F$20,Settings!$G$5:$G$20)) -> 32579.186 | N11: 360000000 | O11: =K11-M11 -> 76018.1 | P11: =L11-N11 -> 840000000 | Q11: Bank o'tkazmasi | R11: Tushum | S11: 44950 | T11: To'langan | U11: Yakuniy 30%
A12: 10 | B12: PRJ-005 | C12: 44963 | D12: Nukus Biznes Markazi | E12: Nukus Biznes Markazi — avans 40% | G12: Nukus Development | H12: Karimov Davron | I12: Qoraboyev Otabek | J12: SH-005 | K12: =IF(L12=0,0,L12/LOOKUP(C12,Settings!$F$5:$F$20,Settings!$G$5:$G$20)) -> 33928.571 | L12: 380000000 | M12: =IF(N12=0,0,N12/LOOKUP(C12,Settings!$F$5:$F$20,Settings!$G$5:$G$20)) -> 13571.429 | N12: 152000000 | O12: =K12-M12 -> 20357.143 | P12: =L12-N12 -> 228000000 | Q12: Bank o'tkazmasi | R12: Tushum | S12: 44993 | T12: To'langan | U12: Avans 40%
A13: 11 | B13: PRJ-004 | C13: 44984 | D13: Chilonzor Turar-joy | E13: Chilonzor Turar-joy — 2-to'lov 30% | G13: Ideal House LLC | H13: Aliyev Sardor | I13: Abdullayev Ravshan | J13: SH-004 | K13: =IF(L13=0,0,L13/LOOKUP(C13,Settings!$F$5:$F$20,Settings!$G$5:$G$20)) -> 37500 | L13: 420000000 | M13: =IF(N13=0,0,N13/LOOKUP(C13,Settings!$F$5:$F$20,Settings!$G$5:$G$20)) -> 11250 | N13: 126000000 | O13: =K13-M13 -> 26250 | P13: =L13-N13 -> 294000000 | Q13: Bank o'tkazmasi | R13: Tushum | S13: 44999 | T13: To'langan | U13: 2-bosqich 30%
A14: 12 | B14: PRJ-003 | C14: 44997 | D14: Buxoro Madaniyat Markazi | E14: Buxoro Madaniyat Markazi — yakuniy 30% | G14: Buxoro Hokimligi | H14: Rahimov Jasur | I14: Xasanov Nodir | J14: SH-003 | K14: =IF(L14=0,0,L14/LOOKUP(C14,Settings!$F$5:$F$20,Settings!$G$5:$G$20)) -> 58035.714 | L14: 650000000 | M14: =IF(N14=0,0,N14/LOOKUP(C14,Settings!$F$5:$F$20,Settings!$G$5:$G$20)) -> 17410.714 | N14: 195000000 | O14: =K14-M14 -> 40625 | P14: =L14-N14 -> 455000000 | Q14: Bank o'tkazmasi | R14: Tushum | S14: 45027 | T14: To'langan | U14: Yakuniy 30%
... A62: 60 | B62: PRJ-020 | C62: 46117 | D62: Toshkent Luxury Villa | E62: Toshkent Luxury Villa — yakuniy 30% | G62: Premium Homes LLC | H62: Aliyev Sardor | I62: Muminov Alisher | J62: SH-020 | K62: =IF(L62=0,0,L62/LOOKUP(C62,Settings!$F$5:$F$20,Settings!$G$5:$G$20)) -> 24902.724 | L62: 320000000 | M62: =IF(N62=0,0,N62/LOOKUP(C62,Settings!$F$5:$F$20,Settings!$G$5:$G$20)) -> 7470.8171 | N62: 96000000 | O62: =K62-M62 -> 17431.907 | P62: =L62-N62 -> 224000000 | Q62: Bank o'tkazmasi | R62: Tushum | S62: 46147 | T62: Kutilmoqda | U62: Yakuniy 30%
A63: 61 | B63: PRJ-001 | C63: 44769 | D63: Toshkent City Tower | F63: Outsourcing — konstruktiv hisob | G63: Toshkent Invest LLC | H63: Aliyev Sardor | I63: Nazarov Ilhom | J63: SH-001 | K63: =IF(L63=0,0,L63/LOOKUP(C63,Settings!$F$5:$F$20,Settings!$G$5:$G$20)) -> 78341.014 | L63: 850000000 | M63: =IF(N63=0,0,N63/LOOKUP(C63,Settings!$F$5:$F$20,Settings!$G$5:$G$20)) -> 3839.2041 | N63: 41655364 | O63: =K63-M63 -> 74501.81 | P63: =L63-N63 -> 808344636 | Q63: Bank o'tkazmasi | R63: Outsourcing | S63: 44784 | T63: Kutilmoqda | U63: StroyExpert LLC
A64: 62 | B64: PRJ-001 | C64: 44774 | D64: Toshkent City Tower | F64: Outsourcing — ekspertiza | G64: Toshkent Invest LLC | H64: Aliyev Sardor | I64: Sotvoldiyev Jasur | J64: SH-001 | K64: =IF(L64=0,0,L64/LOOKUP(C64,Settings!$F$5:$F$20,Settings!$G$5:$G$20)) -> 78341.014 | L64: 850000000 | M64: =IF(N64=0,0,N64/LOOKUP(C64,Settings!$F$5:$F$20,Settings!$G$5:$G$20)) -> 3170.88 | N64: 34404048 | O64: =K64-M64 -> 75170.134 | P64: =L64-N64 -> 815595952 | Q64: Bank o'tkazmasi | R64: Outsourcing | S64: 44789 | T64: To'langan | U64: Viz Studio
A65: 63 | B65: PRJ-001 | C65: 44778 | D65: Toshkent City Tower | F65: Material — chop etish | G65: Toshkent Invest LLC | H65: Aliyev Sardor | I65: Karimov Botir | J65: SH-001 | K65: =IF(L65=0,0,L65/LOOKUP(C65,Settings!$F$5:$F$20,Settings!$G$5:$G$20)) -> 78341.014 | L65: 850000000 | M65: =IF(N65=0,0,N65/LOOKUP(C65,Settings!$F$5:$F$20,Settings!$G$5:$G$20)) -> 1778.3069 | N65: 19294630 | O65: =K65-M65 -> 76562.707 | P65: =L65-N65 -> 830705370 | Q65: Naqd | R65: Material | S65: 44788 | T65: To'langan
A66: 64 | B66: PRJ-002 | C66: 44796 | D66: Samarqand Hotel | F66: Material — chop etish | G66: Silk Road Hotels | H66: Karimov Davron | I66: Tursunov Akmal | J66: SH-002 | K66: =IF(L66=0,0,L66/LOOKUP(C66,Settings!$F$5:$F$20,Settings!$G$5:$G$20)) -> 110599.08 | L66: 1200000000 | M66: =IF(N66=0,0,N66/LOOKUP(C66,Settings!$F$5:$F$20,Settings!$G$5:$G$20)) -> 1252.3987 | N66: 13588526 | O66: =K66-M66 -> 109346.68 | P66: =L66-N66 -> 1186411474 | Q66: Naqd | R66: Material | S66: 44806 | T66: To'langan
A67: 65 | B67: PRJ-002 | C67: 44817 | D67: Samarqand Hotel | F67: Outsourcing — elektr loyiha | G67: Silk Road Hotels | H67: Karimov Davron | I67: Sotvoldiyev Jasur | J67: SH-002 | K67: =IF(L67=0,0,L67/LOOKUP(C67,Settings!$F$5:$F$20,Settings!$G$5:$G$20)) -> 110599.08 | L67: 1200000000 | M67: =IF(N67=0,0,N67/LOOKUP(C67,Settings!$F$5:$F$20,Settings!$G$5:$G$20)) -> 7123.4762 | N67: 77289717 | O67: =K67-M67 -> 103475.6 | P67: =L67-N67 -> 1122710283 | Q67: Naqd | R67: Outsourcing | S67: 44832 | T67: Kutilmoqda | U67: Viz Studio
A68: 66 | B68: PRJ-002 | C68: 44842 | D68: Samarqand Hotel | F68: Outsourcing — geodeziya | G68: Silk Road Hotels | H68: Karimov Davron | I68: Abdullayev Kamol | J68: SH-002 | K68: =IF(L68=0,0,L68/LOOKUP(C68,Settings!$F$5:$F$20,Settings!$G$5:$G$20)) -> 108597.29 | L68: 1200000000 | M68: =IF(N68=0,0,N68/LOOKUP(C68,Settings!$F$5:$F$20,Settings!$G$5:$G$20)) -> 7720.195 | N68: 85308155 | O68: =K68-M68 -> 100877.09 | P68: =L68-N68 -> 1114691845 | Q68: Bank o'tkazmasi | R68: Outsourcing | S68: 44857 | T68: Kutilmoqda | U68: GeoTech LLC
A69: 67 | B69: PRJ-003 | C69: 44858 | D69: Buxoro Madaniyat Markazi | F69: Transport — yetkazish | G69: Buxoro Hokimligi | H69: Rahimov Jasur | I69: Tursunov Akmal | J69: SH-003 | K69: =IF(L69=0,0,L69/LOOKUP(C69,Settings!$F$5:$F$20,Settings!$G$5:$G$20)) -> 58823.529 | L69: 650000000 | M69: =IF(N69=0,0,N69/LOOKUP(C69,Settings!$F$5:$F$20,Settings!$G$5:$G$20)) -> 899.859 | N69: 9943442 | O69: =K69-M69 -> 57923.67 | P69: =L69-N69 -> 640056558 | Q69: Naqd | R69: Transport | S69: 44868 | T69: To'langan
A70: 68 | B70: PRJ-003 | C70: 44900 | D70: Buxoro Madaniyat Markazi | F70: Outsourcing — vizualizatsiya | G70: Buxoro Hokimligi | H70: Rahimov Jasur | I70: Tojiboyev Sanjar | J70: SH-003 | K70: =IF(L70=0,0,L70/LOOKUP(C70,Settings!$F$5:$F$20,Settings!$G$5:$G$20)) -> 58823.529 | L70: 650000000 | M70: =IF(N70=0,0,N70/LOOKUP(C70,Settings!$F$5:$F$20,Settings!$G$5:$G$20)) -> 4366.7151 | N70: 48252202 | O70: =K70-M70 -> 54456.814 | P70: =L70-N70 -> 601747798 | Q70: Karta | R70: Outsourcing | S70: 44915 | T70: Kutilmoqda | U70: CalcPro LLC
A71: 69 | B71: PRJ-004 | C71: 44925 | D71: Chilonzor Turar-joy | F71: Transport — yetkazish | G71: Ideal House LLC | H71: Aliyev Sardor | I71: Xolmatov Doniyor | J71: SH-004 | K71: =IF(L71=0,0,L71/LOOKUP(C71,Settings!$F$5:$F$20,Settings!$G$5:$G$20)) -> 38009.05 | L71: 420000000 | M71: =IF(N71=0,0,N71/LOOKUP(C71,Settings!$F$5:$F$20,Settings!$G$5:$G$20)) -> 833.07348 | N71: 9205462 | O71: =K71-M71 -> 37175.976 | P71: =L71-N71 -> 410794538 | Q71: Naqd | R71: Transport | S71: 44935 | T71: To'langan
A72: 70 | B72: PRJ-004 | C72: 44950 | D72: Chilonzor Turar-joy | F72: Outsourcing — konstruktiv hisob | G72: Ideal House LLC | H72: Aliyev Sardor | I72: Tojiboyev Sanjar | J72: SH-004 | K72: =IF(L72=0,0,L72/LOOKUP(C72,Settings!$F$5:$F$20,Settings!$G$5:$G$20)) -> 37500 | L72: 420000000 | M72: =IF(N72=0,0,N72/LOOKUP(C72,Settings!$F$5:$F$20,Settings!$G$5:$G$20)) -> 2542.0915 | N72: 28471425 | O72: =K72-M72 -> 34957.908 | P72: =L72-N72 -> 391528575 | Q72: Naqd | R72: Outsourcing | S72: 44965 | T72: To'langan | U72: CalcPro LLC
A73: 71 | B73: PRJ-004 | C73: 44955 | D73: Chilonzor Turar-joy | F73: Outsourcing — SME hisob | G73: Ideal House LLC | H73: Aliyev Sardor | I73: Tojiboyev Sanjar | J73: SH-004 | K73: =IF(L73=0,0,L73/LOOKUP(C73,Settings!$F$5:$F$20,Settings!$G$5:$G$20)) -> 37500 | L73: 420000000 | M73: =IF(N73=0,0,N73/LOOKUP(C73,Settings!$F$5:$F$20,Settings!$G$5:$G$20)) -> 1873.8759 | N73: 20987410 | O73: =K73-M73 -> 35626.124 | P73: =L73-N73 -> 399012590 | Q73: Naqd | R73: Outsourcing | S73: 44970 | T73: To'langan | U73: CalcPro LLC
A74: 72 | B74: PRJ-004 | C74: 44958 | D74: Chilonzor Turar-joy | F74: Outsourcing — elektr loyiha | G74: Ideal House LLC | H74: Aliyev Sardor | I74: Nazarov Ilhom | J74: SH-004 | K74: =IF(L74=0,0,L74/LOOKUP(C74,Settings!$F$5:$F$20,Settings!$G$5:$G$20)) -> 37500 | L74: 420000000 | M74: =IF(N74=0,0,N74/LOOKUP(C74,Settings!$F$5:$F$20,Settings!$G$5:$G$20)) -> 1916.5499 | N74: 21465359 | O74: =K74-M74 -> 35583.45 | P74: =L74-N74 -> 398534641 | Q74: Naqd | R74: Outsourcing | S74: 44973 | T74: Kutilmoqda | U74: StroyExpert LLC
A75: 73 | B75: PRJ-005 | C75: 44979 | D75: Nukus Biznes Markazi | F75: Outsourcing — vizualizatsiya | G75: Nukus Development | H75: Karimov Davron | I75: Sotvoldiyev Jasur | J75: SH-005 | K75: =IF(L75=0,0,L75/LOOKUP(C75,Settings!$F$5:$F$20,Settings!$G$5:$G$20)) -> 33928.571 | L75: 380000000 | M75: =IF(N75=0,0,N75/LOOKUP(C75,Settings!$F$5:$F$20,Settings!$G$5:$G$20)) -> 1286.1604 | N75: 14404997 | O75: =K75-M75 -> 32642.411 | P75: =L75-N75 -> 365595003 | Q75: Naqd | R75: Outsourcing | S75: 44994 | T75: Kutilmoqda | U75: Viz Studio
A76: 74 | B76: PRJ-005 | C76: 44987 | D76: Nukus Biznes Markazi | F76: Transport — yetkazish | G76: Nukus Development | H76: Karimov Davron | I76: Xolmatov Doniyor | J76: SH-005 | K76: =IF(L76=0,0,L76/LOOKUP(C76,Settings!$F$5:$F$20,Settings!$G$5:$G$20)) -> 33928.571 | L76: 380000000 | M76: =IF(N76=0,0,N76/LOOKUP(C76,Settings!$F$5:$F$20,Settings!$G$5:$G$20)) -> 683.77116 | N76: 7658237 | O76: =K76-M76 -> 33244.8 | P76: =L76-N76 -> 372341763 | Q76: Naqd | R76: Transport | S76: 44997 | T76: To'langan
A77: 75 | B77: PRJ-005 | C77: 45004 | D77: Nukus Biznes Markazi | F77: Outsourcing — SME hisob | G77: Nukus Development | H77: Karimov Davron | I77: Nazarov Ilhom | J77: SH-005 | K77: =IF(L77=0,0,L77/LOOKUP(C77,Settings!$F$5:$F$20,Settings!$G$5:$G$20)) -> 33928.571 | L77: 380000000 | M77: =IF(N77=0,0,N77/LOOKUP(C77,Settings!$F$5:$F$20,Settings!$G$5:$G$20)) -> 2566.065 | N77: 28739928 | O77: =K77-M77 -> 31362.506 | P77: =L77-N77 -> 351260072 | Q77: Karta | R77: Outsourcing | S77: 45019 | T77: Kutilmoqda | U77: StroyExpert LLC
A78: 76 | B78: PRJ-005 | C78: 45018 | D78: Nukus Biznes Markazi | F78: Outsourcing — elektr loyiha | G78: Nukus Development | H78: Karimov Davron | I78: Abdullayev Kamol | J78: SH-005 | K78: =IF(L78=0,0,L78/LOOKUP(C78,Settings!$F$5:$F$20,Settings!$G$5:$G$20)) -> 33480.176 | L78: 380000000 | M78: =IF(N78=0,0,N78/LOOKUP(C78,Settings!$F$5:$F$20,Settings!$G$5:$G$20)) -> 2485.5489 | N78: 28210980 | O78: =K78-M78 -> 30994.627 | P78: =L78-N78 -> 351789020 | Q78: Bank o'tkazmasi | R78: Outsourcing | S78: 45033 | T78: Kutilmoqda | U78: GeoTech LLC
A79: 77 | B79: PRJ-006 | C79: 45035 | D79: Fargona Shopping Mall | F79: Material — chop etish | G79: Fargona Trade LLC | H79: Toshmatov Bekzod | I79: Karimov Botir | J79: SH-006 | K79: =IF(L79=0,0,L79/LOOKUP(C79,Settings!$F$5:$F$20,Settings!$G$5:$G$20)) -> 83700.441 | L79: 950000000 | M79: =IF(N79=0,0,N79/LOOKUP(C79,Settings!$F$5:$F$20,Settings!$G$5:$G$20)) -> 1941.433 | N79: 22035265 | O79: =K79-M79 -> 81759.007 | P79: =L79-N79 -> 927964735 | Q79: Naqd | R79: Material | S79: 45045 | T79: To'langan
A80: 78 | B80: PRJ-006 | C80: 45041 | D80: Fargona Shopping Mall | F80: Outsourcing — vizualizatsiya | G80: Fargona Trade LLC | H80: Toshmatov Bekzod | I80: Xolmatov Sanjarbek | J80: SH-006 | K80: =IF(L80=0,0,L80/LOOKUP(C80,Settings!$F$5:$F$20,Settings!$G$5:$G$20)) -> 83700.441 | L80: 950000000 | M80: =IF(N80=0,0,N80/LOOKUP(C80,Settings!$F$5:$F$20,Settings!$G$5:$G$20)) -> 5926.0885 | N80: 67261104 | O80: =K80-M80 -> 77774.352 | P80: =L80-N80 -> 882738896 | Q80: Karta | R80: Outsourcing | S80: 45056 | T80: To'langan | U80: MEP Solutions
A81: 79 | B81: PRJ-006 | C81: 45043 | D81: Fargona Shopping Mall | F81: Outsourcing — ekspertiza | G81: Fargona Trade LLC | H81: Toshmatov Bekzod | I81: Sotvoldiyev Jasur | J81: SH-006 | K81: =IF(L81=0,0,L81/LOOKUP(C81,Settings!$F$5:$F$20,Settings!$G$5:$G$20)) -> 83700.441 | L81: 950000000 | M81: =IF(N81=0,0,N81/LOOKUP(C81,Settings!$F$5:$F$20,Settings!$G$5:$G$20)) -> 3513.1263 | N81: 39873984 | O81: =K81-M81 -> 80187.314 | P81: =L81-N81 -> 910126016 | Q81: Naqd | R81: Outsourcing | S81: 45058 | T81: To'langan | U81: Viz Studio
A82: 80 | B82: PRJ-006 | C82: 45085 | D82: Fargona Shopping Mall | F82: Outsourcing — konstruktiv hisob | G82: Fargona Trade LLC | H82: Toshmatov Bekzod | I82: Mirzayev Akmal | J82: SH-006 | K82: =IF(L82=0,0,L82/LOOKUP(C82,Settings!$F$5:$F$20,Settings!$G$5:$G$20)) -> 83700.441 | L82: 950000000 | M82: =IF(N82=0,0,N82/LOOKUP(C82,Settings!$F$5:$F$20,Settings!$G$5:$G$20)) -> 5017.6094 | N82: 56949867 | O82: =K82-M82 -> 78682.831 | P82: =L82-N82 -> 893050133 | Q82: Bank o'tkazmasi | R82: Outsourcing | S82: 45100 | T82: To'langan | U82: ElectroPlan
A83: 81 | B83: PRJ-007 | C83: 45105 | D83: Toshkent Metro Stansiya | F83: Material — chop etish | G83: Toshkent Metro | H83: Rahimov Jasur | I83: Tursunov Akmal | J83: SH-007 | K83: =IF(L83=0,0,L83/LOOKUP(C83,Settings!$F$5:$F$20,Settings!$G$5:$G$20)) -> 132158.59 | L83: 1500000000 | M83: =IF(N83=0,0,N83/LOOKUP(C83,Settings!$F$5:$F$20,Settings!$G$5:$G$20)) -> 1377.183 | N83: 15631027 | O83: =K83-M83 -> 130781.41 | P83: =L83-N83 -> 1484368973 | Q83: Naqd | R83: Material | S83: 45115 | T83: To'langan
A84: 82 | B84: PRJ-007 | C84: 45128 | D84: Toshkent Metro Stansiya | F84: Outsourcing — vizualizatsiya | G84: Toshkent Metro | H84: Rahimov Jasur | I84: Mirzayev Akmal | J84: SH-007 | K84: =IF(L84=0,0,L84/LOOKUP(C84,Settings!$F$5:$F$20,Settings!$G$5:$G$20)) -> 130434.78 | L84: 1500000000 | M84: =IF(N84=0,0,N84/LOOKUP(C84,Settings!$F$5:$F$20,Settings!$G$5:$G$20)) -> 4702.2012 | N84: 54075314 | O84: =K84-M84 -> 125732.58 | P84: =L84-N84 -> 1445924686 | Q84: Naqd | R84: Outsourcing | S84: 45143 | T84: To'langan | U84: ElectroPlan
A85: 83 | B85: PRJ-007 | C85: 45138 | D85: Toshkent Metro Stansiya | F85: Outsourcing — geodeziya | G85: Toshkent Metro | H85: Rahimov Jasur | I85: Tojiboyev Sanjar | J85: SH-007 | K85: =IF(L85=0,0,L85/LOOKUP(C85,Settings!$F$5:$F$20,Settings!$G$5:$G$20)) -> 130434.78 | L85: 1500000000 | M85: =IF(N85=0,0,N85/LOOKUP(C85,Settings!$F$5:$F$20,Settings!$G$5:$G$20)) -> 9971.1749 | N85: 114668511 | O85: =K85-M85 -> 120463.61 | P85: =L85-N85 -> 1385331489 | Q85: Karta | R85: Outsourcing | S85: 45153 | T85: To'langan | U85: CalcPro LLC
A86: 84 | B86: PRJ-007 | C86: 45145 | D86: Toshkent Metro Stansiya | F86: Outsourcing — vizualizatsiya | G86: Toshkent Metro | H86: Rahimov Jasur | I86: Sotvoldiyev Jasur | J86: SH-007 | K86: =IF(L86=0,0,L86/LOOKUP(C86,Settings!$F$5:$F$20,Settings!$G$5:$G$20)) -> 130434.78 | L86: 1500000000 | M86: =IF(N86=0,0,N86/LOOKUP(C86,Settings!$F$5:$F$20,Settings!$G$5:$G$20)) -> 10403.148 | N86: 119636201 | O86: =K86-M86 -> 120031.63 | P86: =L86-N86 -> 1380363799 | Q86: Karta | R86: Outsourcing | S86: 45160 | T86: Kutilmoqda | U86: Viz Studio
A87: 85 | B87: PRJ-008 | C87: 45164 | D87: Namangan Klinika | F87: Outsourcing — elektr loyiha | G87: Namangan Med | H87: Aliyev Sardor | I87: Xolmatov Sanjarbek | J87: SH-008 | K87: =IF(L87=0,0,L87/LOOKUP(C87,Settings!$F$5:$F$20,Settings!$G$5:$G$20)) -> 47826.087 | L87: 550000000 | M87: =IF(N87=0,0,N87/LOOKUP(C87,Settings!$F$5:$F$20,Settings!$G$5:$G$20)) -> 1575.5677 | N87: 18119028 | O87: =K87-M87 -> 46250.519 | P87: =L87-N87 -> 531880972 | Q87: Naqd | R87: Outsourcing | S87: 45179 | T87: To'langan | U87: MEP Solutions
A88: 86 | B88: PRJ-008 | C88: 45165 | D88: Namangan Klinika | F88: Transport — yetkazish | G88: Namangan Med | H88: Aliyev Sardor | I88: Tursunov Akmal | J88: SH-008 | K88: =IF(L88=0,0,L88/LOOKUP(C88,Settings!$F$5:$F$20,Settings!$G$5:$G$20)) -> 47826.087 | L88: 550000000 | M88: =IF(N88=0,0,N88/LOOKUP(C88,Settings!$F$5:$F$20,Settings!$G$5:$G$20)) -> 546.03739 | N88: 6279430 | O88: =K88-M88 -> 47280.05 | P88: =L88-N88 -> 543720570 | Q88: Naqd | R88: Transport | S88: 45175 | T88: To'langan
...

Sheet MIZAN
A2: No | B2: No ID | C2: sana | D2: Tushum nomi | E2: Harajat nomi | F2: mas'ul shaxs | G2: Kim yoki kimga to'langan | H2: Hujjat ID | I2: Shartnoma (UZS) | J2: Summa (UZS) | K2: Qoldiq (UZS) | L2: Shartnoma (USD) | M2: Summa (USD) | N2: Qoldiq (USD) | O2: sharx
A3: 1 | B3: MZ-0006 | C3: 44747 | E3: Dasturlar litsenziya | F3: Xolmatov Ulugbek | G3: Kamolov Rustam | H3: MZ-0006 | J3: 32000000 | K3: =I3-J3 -> -32000000 | L3: =IF(I3=0,0,I3/LOOKUP(C3,Settings!$F$5:$F$20,Settings!$G$5:$G$20)) -> 0 | M3: =IF(J3=0,0,J3/LOOKUP(C3,Settings!$F$5:$F$20,Settings!$G$5:$G$20)) -> 2949.3088 | N3: =L3-M3 -> -2949.3088 | O3: Yillik
A4: 2 | B4: MZ-0009 | C4: 44751 | E4: Malaka oshirish | F4: Azimov Bobur | G4: Xasanova Dilfuza | H4: MZ-0009 | J4: 4432780 | K4: =I4-J4 -> -4432780 | L4: =IF(I4=0,0,I4/LOOKUP(C4,Settings!$F$5:$F$20,Settings!$G$5:$G$20)) -> 0 | M4: =IF(J4=0,0,J4/LOOKUP(C4,Settings!$F$5:$F$20,Settings!$G$5:$G$20)) -> 408.55115 | N4: =L4-M4 -> -408.55115
A5: 3 | B5: MZ-0004 | C5: 44752 | E5: Ofis ijarasi | F5: Kamolov Rustam | G5: Kamolov Rustam | H5: MZ-0004 | J5: 15000000 | K5: =I5-J5 -> -15000000 | L5: =IF(I5=0,0,I5/LOOKUP(C5,Settings!$F$5:$F$20,Settings!$G$5:$G$20)) -> 0 | M5: =IF(J5=0,0,J5/LOOKUP(C5,Settings!$F$5:$F$20,Settings!$G$5:$G$20)) -> 1382.4885 | N5: =L5-M5 -> -1382.4885
A6: 4 | B6: MZ-0005 | C6: 44757 | E6: Ovqat xarajatlari | F6: Kamolov Rustam | G6: Kamolov Rustam | H6: MZ-0005 | J6: 9378610 | K6: =I6-J6 -> -9378610 | L6: =IF(I6=0,0,I6/LOOKUP(C6,Settings!$F$5:$F$20,Settings!$G$5:$G$20)) -> 0 | M6: =IF(J6=0,0,J6/LOOKUP(C6,Settings!$F$5:$F$20,Settings!$G$5:$G$20)) -> 864.38802 | N6: =L6-M6 -> -864.38802
A7: 5 | B7: MZ-0008 | C7: 44757 | E7: Kommunal to'lovlar | F7: Kamolov Rustam | G7: Kamolov Rustam | H7: MZ-0008 | J7: 6776176 | K7: =I7-J7 -> -6776176 | L7: =IF(I7=0,0,I7/LOOKUP(C7,Settings!$F$5:$F$20,Settings!$G$5:$G$20)) -> 0 | M7: =IF(J7=0,0,J7/LOOKUP(C7,Settings!$F$5:$F$20,Settings!$G$5:$G$20)) -> 624.53235 | N7: =L7-M7 -> -624.53235
A8: 6 | B8: MZ-0001 | C8: 44762 | D8: PRJ-001 MIZAN ulushi | F8: MIZAN | G8: Raximova Shaxlo | H8: SH-001 | J8: 129606840 | K8: =I8-J8 -> -129606840 | L8: =IF(I8=0,0,I8/LOOKUP(C8,Settings!$F$5:$F$20,Settings!$G$5:$G$20)) -> 0 | M8: =IF(J8=0,0,J8/LOOKUP(C8,Settings!$F$5:$F$20,Settings!$G$5:$G$20)) -> 11945.331 | N8: =L8-M8 -> -11945.331 | O8: Proekt ulushi
A9: 7 | B9: MZ-0007 | C9: 44762 | E9: Soliqlar | F9: Sobirova Malika | G9: Sobirova Malika | H9: MZ-0007 | J9: 90859101 | K9: =I9-J9 -> -90859101 | L9: =IF(I9=0,0,I9/LOOKUP(C9,Settings!$F$5:$F$20,Settings!$G$5:$G$20)) -> 0 | M9: =IF(J9=0,0,J9/LOOKUP(C9,Settings!$F$5:$F$20,Settings!$G$5:$G$20)) -> 8374.1107 | N9: =L9-M9 -> -8374.1107
A10: 8 | B10: MZ-0002 | C10: 44770 | E10: Xodimlar ish haqi | F10: Sobirova Malika | G10: Sobirova Malika | H10: MZ-0002 | J10: 357000000 | K10: =I10-J10 -> -357000000 | L10: =IF(I10=0,0,I10/LOOKUP(C10,Settings!$F$5:$F$20,Settings!$G$5:$G$20)) -> 0 | M10: =IF(J10=0,0,J10/LOOKUP(C10,Settings!$F$5:$F$20,Settings!$G$5:$G$20)) -> 32903.226 | N10: =L10-M10 -> -32903.226 | O10: 22 xodim
A11: 9 | B11: MZ-0003 | C11: 44770 | E11: Premiyalar | F11: Sobirova Malika | G11: Raximova Shaxlo | H11: MZ-0003 | J11: 43629074 | K11: =I11-J11 -> -43629074 | L11: =IF(I11=0,0,I11/LOOKUP(C11,Settings!$F$5:$F$20,Settings!$G$5:$G$20)) -> 0 | M11: =IF(J11=0,0,J11/LOOKUP(C11,Settings!$F$5:$F$20,Settings!$G$5:$G$20)) -> 4021.1128 | N11: =L11-M11 -> -4021.1128
A12: 10 | B12: MZ-0013 | C12: 44783 | E12: Ofis ijarasi | F12: Kamolov Rustam | G12: Kamolov Rustam | H12: MZ-0013 | J12: 15000000 | K12: =I12-J12 -> -15000000 | L12: =IF(I12=0,0,I12/LOOKUP(C12,Settings!$F$5:$F$20,Settings!$G$5:$G$20)) -> 0 | M12: =IF(J12=0,0,J12/LOOKUP(C12,Settings!$F$5:$F$20,Settings!$G$5:$G$20)) -> 1382.4885 | N12: =L12-M12 -> -1382.4885
A13: 11 | B13: MZ-0014 | C13: 44788 | E13: Ovqat xarajatlari | F13: Kamolov Rustam | G13: Kamolov Rustam | H13: MZ-0014 | J13: 7906208 | K13: =I13-J13 -> -7906208 | L13: =IF(I13=0,0,I13/LOOKUP(C13,Settings!$F$5:$F$20,Settings!$G$5:$G$20)) -> 0 | M13: =IF(J13=0,0,J13/LOOKUP(C13,Settings!$F$5:$F$20,Settings!$G$5:$G$20)) -> 728.68276 | N13: =L13-M13 -> -728.68276
A14: 12 | B14: MZ-0016 | C14: 44788 | E14: Kommunal to'lovlar | F14: Kamolov Rustam | G14: Kamolov Rustam | H14: MZ-0016 | J14: 6925742 | K14: =I14-J14 -> -6925742 | L14: =IF(I14=0,0,I14/LOOKUP(C14,Settings!$F$5:$F$20,Settings!$G$5:$G$20)) -> 0 | M14: =IF(J14=0,0,J14/LOOKUP(C14,Settings!$F$5:$F$20,Settings!$G$5:$G$20)) -> 638.31724 | N14: =L14-M14 -> -638.31724
A15: 13 | B15: MZ-0010 | C15: 44793 | D15: PRJ-002 MIZAN ulushi | F15: MIZAN | G15: Raximova Shaxlo | H15: SH-002 | J15: 264153382 | K15: =I15-J15 -> -264153382 | L15: =IF(I15=0,0,I15/LOOKUP(C15,Settings!$F$5:$F$20,Settings!$G$5:$G$20)) -> 0 | M15: =IF(J15=0,0,J15/LOOKUP(C15,Settings!$F$5:$F$20,Settings!$G$5:$G$20)) -> 24345.934 | N15: =L15-M15 -> -24345.934 | O15: Proekt ulushi
A16: 14 | B16: MZ-0015 | C16: 44793 | E16: Soliqlar | F16: Sobirova Malika | G16: Sobirova Malika | H16: MZ-0015 | J16: 80531880 | K16: =I16-J16 -> -80531880 | L16: =IF(I16=0,0,I16/LOOKUP(C16,Settings!$F$5:$F$20,Settings!$G$5:$G$20)) -> 0 | M16: =IF(J16=0,0,J16/LOOKUP(C16,Settings!$F$5:$F$20,Settings!$G$5:$G$20)) -> 7422.2931 | N16: =L16-M16 -> -7422.2931
A17: 15 | B17: MZ-0011 | C17: 44801 | E17: Xodimlar ish haqi | F17: Sobirova Malika | G17: Sobirova Malika | H17: MZ-0011 | J17: 357000000 | K17: =I17-J17 -> -357000000 | L17: =IF(I17=0,0,I17/LOOKUP(C17,Settings!$F$5:$F$20,Settings!$G$5:$G$20)) -> 0 | M17: =IF(J17=0,0,J17/LOOKUP(C17,Settings!$F$5:$F$20,Settings!$G$5:$G$20)) -> 32903.226 | N17: =L17-M17 -> -32903.226 | O17: 22 xodim
A18: 16 | B18: MZ-0012 | C18: 44801 | E18: Premiyalar | F18: Sobirova Malika | G18: Raximova Shaxlo | H18: MZ-0012 | J18: 34018230 | K18: =I18-J18 -> -34018230 | L18: =IF(I18=0,0,I18/LOOKUP(C18,Settings!$F$5:$F$20,Settings!$G$5:$G$20)) -> 0 | M18: =IF(J18=0,0,J18/LOOKUP(C18,Settings!$F$5:$F$20,Settings!$G$5:$G$20)) -> 3135.3207 | N18: =L18-M18 -> -3135.3207
A19: 17 | B19: MZ-0019 | C19: 44814 | E19: Ofis ijarasi | F19: Kamolov Rustam | G19: Kamolov Rustam | H19: MZ-0019 | J19: 15000000 | K19: =I19-J19 -> -15000000 | L19: =IF(I19=0,0,I19/LOOKUP(C19,Settings!$F$5:$F$20,Settings!$G$5:$G$20)) -> 0 | M19: =IF(J19=0,0,J19/LOOKUP(C19,Settings!$F$5:$F$20,Settings!$G$5:$G$20)) -> 1382.4885 | N19: =L19-M19 -> -1382.4885
A20: 18 | B20: MZ-0020 | C20: 44819 | E20: Ovqat xarajatlari | F20: Kamolov Rustam | G20: Kamolov Rustam | H20: MZ-0020 | J20: 7113355 | K20: =I20-J20 -> -7113355 | L20: =IF(I20=0,0,I20/LOOKUP(C20,Settings!$F$5:$F$20,Settings!$G$5:$G$20)) -> 0 | M20: =IF(J20=0,0,J20/LOOKUP(C20,Settings!$F$5:$F$20,Settings!$G$5:$G$20)) -> 655.60876 | N20: =L20-M20 -> -655.60876
A21: 19 | B21: MZ-0022 | C21: 44819 | E21: Kommunal to'lovlar | F21: Kamolov Rustam | G21: Kamolov Rustam | H21: MZ-0022 | J21: 5495781 | K21: =I21-J21 -> -5495781 | L21: =IF(I21=0,0,I21/LOOKUP(C21,Settings!$F$5:$F$20,Settings!$G$5:$G$20)) -> 0 | M21: =IF(J21=0,0,J21/LOOKUP(C21,Settings!$F$5:$F$20,Settings!$G$5:$G$20)) -> 506.52359 | N21: =L21-M21 -> -506.52359
A22: 20 | B22: MZ-0021 | C22: 44824 | E22: Soliqlar | F22: Sobirova Malika | G22: Sobirova Malika | H22: MZ-0021 | J22: 88422328 | K22: =I22-J22 -> -88422328 | L22: =IF(I22=0,0,I22/LOOKUP(C22,Settings!$F$5:$F$20,Settings!$G$5:$G$20)) -> 0 | M22: =IF(J22=0,0,J22/LOOKUP(C22,Settings!$F$5:$F$20,Settings!$G$5:$G$20)) -> 8149.5233 | N22: =L22-M22 -> -8149.5233
A23: 21 | B23: MZ-0017 | C23: 44832 | E23: Xodimlar ish haqi | F23: Sobirova Malika | G23: Sobirova Malika | H23: MZ-0017 | J23: 357000000 | K23: =I23-J23 -> -357000000 | L23: =IF(I23=0,0,I23/LOOKUP(C23,Settings!$F$5:$F$20,Settings!$G$5:$G$20)) -> 0 | M23: =IF(J23=0,0,J23/LOOKUP(C23,Settings!$F$5:$F$20,Settings!$G$5:$G$20)) -> 32903.226 | N23: =L23-M23 -> -32903.226 | O23: 22 xodim
A24: 22 | B24: MZ-0018 | C24: 44832 | E24: Premiyalar | F24: Sobirova Malika | G24: Raximova Shaxlo | H24: MZ-0018 | J24: 61285829 | K24: =I24-J24 -> -61285829 | L24: =IF(I24=0,0,I24/LOOKUP(C24,Settings!$F$5:$F$20,Settings!$G$5:$G$20)) -> 0 | M24: =IF(J24=0,0,J24/LOOKUP(C24,Settings!$F$5:$F$20,Settings!$G$5:$G$20)) -> 5648.4635 | N24: =L24-M24 -> -5648.4635
A25: 23 | B25: MZ-0026 | C25: 44844 | E25: Ofis ijarasi | F25: Kamolov Rustam | G25: Kamolov Rustam | H25: MZ-0026 | J25: 15000000 | K25: =I25-J25 -> -15000000 | L25: =IF(I25=0,0,I25/LOOKUP(C25,Settings!$F$5:$F$20,Settings!$G$5:$G$20)) -> 0 | M25: =IF(J25=0,0,J25/LOOKUP(C25,Settings!$F$5:$F$20,Settings!$G$5:$G$20)) -> 1357.4661 | N25: =L25-M25 -> -1357.4661
A26: 24 | B26: MZ-0027 | C26: 44849 | E26: Ovqat xarajatlari | F26: Kamolov Rustam | G26: Kamolov Rustam | H26: MZ-0027 | J26: 8030098 | K26: =I26-J26 -> -8030098 | L26: =IF(I26=0,0,I26/LOOKUP(C26,Settings!$F$5:$F$20,Settings!$G$5:$G$20)) -> 0 | M26: =IF(J26=0,0,J26/LOOKUP(C26,Settings!$F$5:$F$20,Settings!$G$5:$G$20)) -> 726.7057 | N26: =L26-M26 -> -726.7057
A27: 25 | B27: MZ-0029 | C27: 44849 | E27: Kommunal to'lovlar | F27: Kamolov Rustam | G27: Kamolov Rustam | H27: MZ-0029 | J27: 6720068 | K27: =I27-J27 -> -6720068 | L27: =IF(I27=0,0,I27/LOOKUP(C27,Settings!$F$5:$F$20,Settings!$G$5:$G$20)) -> 0 | M27: =IF(J27=0,0,J27/LOOKUP(C27,Settings!$F$5:$F$20,Settings!$G$5:$G$20)) -> 608.15095 | N27: =L27-M27 -> -608.15095
A28: 26 | B28: MZ-0023 | C28: 44854 | D28: PRJ-003 MIZAN ulushi | F28: MIZAN | G28: Raximova Shaxlo | H28: SH-003 | J28: 102012349 | K28: =I28-J28 -> -102012349 | L28: =IF(I28=0,0,I28/LOOKUP(C28,Settings!$F$5:$F$20,Settings!$G$5:$G$20)) -> 0 | M28: =IF(J28=0,0,J28/LOOKUP(C28,Settings!$F$5:$F$20,Settings!$G$5:$G$20)) -> 9231.8868 | N28: =L28-M28 -> -9231.8868 | O28: Proekt ulushi
A29: 27 | B29: MZ-0028 | C29: 44854 | E29: Soliqlar | F29: Sobirova Malika | G29: Sobirova Malika | H29: MZ-0028 | J29: 88756222 | K29: =I29-J29 -> -88756222 | L29: =IF(I29=0,0,I29/LOOKUP(C29,Settings!$F$5:$F$20,Settings!$G$5:$G$20)) -> 0 | M29: =IF(J29=0,0,J29/LOOKUP(C29,Settings!$F$5:$F$20,Settings!$G$5:$G$20)) -> 8032.2373 | N29: =L29-M29 -> -8032.2373
A30: 28 | B30: MZ-0024 | C30: 44862 | E30: Xodimlar ish haqi | F30: Sobirova Malika | G30: Sobirova Malika | H30: MZ-0024 | J30: 357000000 | K30: =I30-J30 -> -357000000 | L30: =IF(I30=0,0,I30/LOOKUP(C30,Settings!$F$5:$F$20,Settings!$G$5:$G$20)) -> 0 | M30: =IF(J30=0,0,J30/LOOKUP(C30,Settings!$F$5:$F$20,Settings!$G$5:$G$20)) -> 32307.692 | N30: =L30-M30 -> -32307.692 | O30: 22 xodim
A31: 29 | B31: MZ-0025 | C31: 44862 | E31: Premiyalar | F31: Sobirova Malika | G31: Raximova Shaxlo | H31: MZ-0025 | J31: 44250035 | K31: =I31-J31 -> -44250035 | L31: =IF(I31=0,0,I31/LOOKUP(C31,Settings!$F$5:$F$20,Settings!$G$5:$G$20)) -> 0 | M31: =IF(J31=0,0,J31/LOOKUP(C31,Settings!$F$5:$F$20,Settings!$G$5:$G$20)) -> 4004.5281 | N31: =L31-M31 -> -4004.5281
A32: 30 | B32: MZ-0035 | C32: 44867 | E32: Malaka oshirish | F32: Azimov Bobur | G32: Xasanova Dilfuza | H32: MZ-0035 | J32: 3975622 | K32: =I32-J32 -> -3975622 | L32: =IF(I32=0,0,I32/LOOKUP(C32,Settings!$F$5:$F$20,Settings!$G$5:$G$20)) -> 0 | M32: =IF(J32=0,0,J32/LOOKUP(C32,Settings!$F$5:$F$20,Settings!$G$5:$G$20)) -> 359.7848 | N32: =L32-M32 -> -359.7848
A33: 31 | B33: MZ-0031 | C33: 44875 | E33: Ofis ijarasi | F33: Kamolov Rustam | G33: Kamolov Rustam | H33: MZ-0031 | J33: 15000000 | K33: =I33-J33 -> -15000000 | L33: =IF(I33=0,0,I33/LOOKUP(C33,Settings!$F$5:$F$20,Settings!$G$5:$G$20)) -> 0 | M33: =IF(J33=0,0,J33/LOOKUP(C33,Settings!$F$5:$F$20,Settings!$G$5:$G$20)) -> 1357.4661 | N33: =L33-M33 -> -1357.4661
A34: 32 | B34: MZ-0032 | C34: 44880 | E34: Ovqat xarajatlari | F34: Kamolov Rustam | G34: Kamolov Rustam | H34: MZ-0032 | J34: 9206522 | K34: =I34-J34 -> -9206522 | L34: =IF(I34=0,0,I34/LOOKUP(C34,Settings!$F$5:$F$20,Settings!$G$5:$G$20)) -> 0 | M34: =IF(J34=0,0,J34/LOOKUP(C34,Settings!$F$5:$F$20,Settings!$G$5:$G$20)) -> 833.16941 | N34: =L34-M34 -> -833.16941
A35: 33 | B35: MZ-0034 | C35: 44880 | E35: Kommunal to'lovlar | F35: Kamolov Rustam | G35: Kamolov Rustam | H35: MZ-0034 | J35: 5996621 | K35: =I35-J35 -> -5996621 | L35: =IF(I35=0,0,I35/LOOKUP(C35,Settings!$F$5:$F$20,Settings!$G$5:$G$20)) -> 0 | M35: =IF(J35=0,0,J35/LOOKUP(C35,Settings!$F$5:$F$20,Settings!$G$5:$G$20)) -> 542.68063 | N35: =L35-M35 -> -542.68063
A36: 34 | B36: MZ-0033 | C36: 44885 | E36: Soliqlar | F36: Sobirova Malika | G36: Sobirova Malika | H36: MZ-0033 | J36: 81588183 | K36: =I36-J36 -> -81588183 | L36: =IF(I36=0,0,I36/LOOKUP(C36,Settings!$F$5:$F$20,Settings!$G$5:$G$20)) -> 0 | M36: =IF(J36=0,0,J36/LOOKUP(C36,Settings!$F$5:$F$20,Settings!$G$5:$G$20)) -> 7383.546 | N36: =L36-M36 -> -7383.546
A37: 35 | B37: MZ-0030 | C37: 44893 | E37: Xodimlar ish haqi | F37: Sobirova Malika | G37: Sobirova Malika | H37: MZ-0030 | J37: 357000000 | K37: =I37-J37 -> -357000000 | L37: =IF(I37=0,0,I37/LOOKUP(C37,Settings!$F$5:$F$20,Settings!$G$5:$G$20)) -> 0 | M37: =IF(J37=0,0,J37/LOOKUP(C37,Settings!$F$5:$F$20,Settings!$G$5:$G$20)) -> 32307.692 | N37: =L37-M37 -> -32307.692 | O37: 22 xodim
A38: 36 | B38: MZ-0039 | C38: 44905 | E38: Ofis ijarasi | F38: Kamolov Rustam | G38: Kamolov Rustam | H38: MZ-0039 | J38: 15000000 | K38: =I38-J38 -> -15000000 | L38: =IF(I38=0,0,I38/LOOKUP(C38,Settings!$F$5:$F$20,Settings!$G$5:$G$20)) -> 0 | M38: =IF(J38=0,0,J38/LOOKUP(C38,Settings!$F$5:$F$20,Settings!$G$5:$G$20)) -> 1357.4661 | N38: =L38-M38 -> -1357.4661
A39: 37 | B39: MZ-0040 | C39: 44910 | E39: Ovqat xarajatlari | F39: Kamolov Rustam | G39: Kamolov Rustam | H39: MZ-0040 | J39: 8339868 | K39: =I39-J39 -> -8339868 | L39: =IF(I39=0,0,I39/LOOKUP(C39,Settings!$F$5:$F$20,Settings!$G$5:$G$20)) -> 0 | M39: =IF(J39=0,0,J39/LOOKUP(C39,Settings!$F$5:$F$20,Settings!$G$5:$G$20)) -> 754.73919 | N39: =L39-M39 -> -754.73919
A40: 38 | B40: MZ-0042 | C40: 44910 | E40: Kommunal to'lovlar | F40: Kamolov Rustam | G40: Kamolov Rustam | H40: MZ-0042 | J40: 5459287 | K40: =I40-J40 -> -5459287 | L40: =IF(I40=0,0,I40/LOOKUP(C40,Settings!$F$5:$F$20,Settings!$G$5:$G$20)) -> 0 | M40: =IF(J40=0,0,J40/LOOKUP(C40,Settings!$F$5:$F$20,Settings!$G$5:$G$20)) -> 494.05312 | N40: =L40-M40 -> -494.05312
A41: 39 | B41: MZ-0036 | C41: 44915 | D41: PRJ-004 MIZAN ulushi | F41: MIZAN | G41: Raximova Shaxlo | H41: SH-004 | J41: 81251677 | K41: =I41-J41 -> -81251677 | L41: =IF(I41=0,0,I41/LOOKUP(C41,Settings!$F$5:$F$20,Settings!$G$5:$G$20)) -> 0 | M41: =IF(J41=0,0,J41/LOOKUP(C41,Settings!$F$5:$F$20,Settings!$G$5:$G$20)) -> 7353.0929 | N41: =L41-M41 -> -7353.0929 | O41: Proekt ulushi
...

Sheet Settings
A1: SOZLAMALAR / SETTINGS
F2: KURS TARIXI
A3: ASOSIY SOZLAMALAR | F3: Kursni qo'shib boring!
A4: Dollar kursi (1 USD) | B4: 12850 | C4: UZS | D4: ⚠️ Kursni o'zgartiring — barcha listlar avtomatik yangilanadi! | F4: Sana | G4: Kurs (UZS/USD)
A5: Toshkent vaqti | B5: =NOW() -> 46081.494 | F5: 44743 | G5: 10850
A6: Oylik ish kunlari | B6: 22 | C6: kun | F6: 44835 | G6: 11050
A7: Kunlik ish soatlari | B7: 8 | C7: soat | F7: 44927 | G7: 11200
A8: Oylik ish soatlari | B8: =B6*B7 -> 176 | C8: soat | F8: 45017 | G8: 11350
A9: Risk koeffitsiyenti (default) | B9: 1.15 | F9: 45108 | G9: 11500
A10: Ishlab chiqarish xodimlari soni | B10: 15 | C10: kishi | F10: 45200 | G10: 11700
A11: Jami xodimlar soni | B11: 22 | C11: kishi | F11: 45292 | G11: 11900
F12: 45383 | G12: 12050
F13: 45474 | G13: 12200
A14: BO'LIMLAR | B14: Kod | C14: Turi | F14: 45566 | G14: 12350
A15: 🏗️ Master Planning | B15: MP | C15: Ishlab chiqarish | F15: 45658 | G15: 12500
A16: 📐 Arxitektura | B16: ARX | C16: Ishlab chiqarish | F16: 45748 | G16: 12600
A17: 🎨 3D Vizualizatsiya | B17: 3D | C17: Ishlab chiqarish | F17: 45839 | G17: 12700
A18: 🛋️ Interior Design | B18: INT | C18: Ishlab chiqarish | F18: 45931 | G18: 12800
A19: 🖼️ Graphic Design | B19: GD | C19: Ishlab chiqarish | F19: 46023 | G19: 12850
A20: 💰 Smeta | B20: SM | C20: Ishlab chiqarish | F20: 46082 | G20: 12850
A21: 🔧 Konstruktor | B21: KON | C21: Ishlab chiqarish
A22: 🏢 Ma'muriyat | B22: ADM | C22: Ma'muriyat (overhead)
A25: KATEGORIYALAR | B25: Kod | D25: TO'LOV TURLARI
A26: Outsourcing | B26: OUT | D26: Naqd
A27: Material | B27: MAT | D27: Bank o'tkazmasi
A28: Transport | B28: TRN | D28: Karta
A29: Ish haqi | B29: ISH | D29: Valyuta hisobi
A30: Ijara | B30: IJA | D30: Ichki hisob
A31: Kommunal | B31: KOM
A32: Ovqat | B32: OVQ | D32: STATUSLAR
A33: Dasturlar/Software | B33: DST | D33: To'langan
A34: Texnika/Jihozlar | B34: TEX | D34: Kutilmoqda
A35: Soliqlar | B35: SOL | D35: Kechikkan
A36: Malaka oshirish | B36: MAL | D36: Bekor qilingan
A37: Marketing | B37: MRK
A38: Premiya | B38: PRM
A39: Boshqa | B39: BSH
A40: Proekt xarajati | B40: PRX
A41: MIZAN | B41: MZN

Sheet Xodimlar va Soat narxi
A1: XODIMLAR VA 1 SOAT NARXI
A3: No | B3: F.I.Sh. | C3: Lavozimi | D3: Bo'lim | E3: Asosiy maosh | F3: Premiya | G3: Soliq (12%) | H3: JSSM (12%) | I3: Jami shaxsiy | J3: Ma'muriyat ulushi | K3: Texnika ulushi | L3: Overhead ulushi | M3: Jami soatlik xarajat | N3: 1 soat narxi (to'liq) | O3: Oylik ish soatlari | P3: Turi | Q3: 1 soat narxi (USD) | R3: Oylik to'liq (USD)
A4: 🏗️ MASTER PLANNING
A5: 1 | B5: Rahimov Jasur | C5: Bo'lim boshlig'i | D5: Master Planning | E5: 22000000 | F5: 4000000 | G5: =(E5+F5)*0.12 -> 3120000 | H5: =(E5+F5)*0.12 -> 3120000 | I5: =E5+F5+G5+H5 -> 32240000 | J5: =I$34/15/Settings!$B$8 -> 58946.97 | K5: ='Texnika va Overhead'!F15/15 -> 3672.138 | L5: ='Texnika va Overhead'!D39 -> 0 | M5: =I5/Settings!$B$8+J5+K5+L5 -> 245800.93 | N5: =M5 -> 245800.93 | O5: =Settings!$B$8 -> 176 | P5: Ishlab chiqarish | Q5: =N5/Settings!$B$4 -> 19.128477 | R5: =Q5*O5 -> 3366.6119
A6: 2 | B6: Azimov Bobur | C6: Master planner | D6: Master Planning | E6: 18000000 | F6: 3500000 | G6: =(E6+F6)*0.12 -> 2580000 | H6: =(E6+F6)*0.12 -> 2580000 | I6: =E6+F6+G6+H6 -> 26660000 | J6: =I$34/15/Settings!$B$8 -> 58946.97 | K6: ='Texnika va Overhead'!F15/15 -> 3672.138 | L6: ='Texnika va Overhead'!D39 -> 0 | M6: =I6/Settings!$B$8+J6+K6+L6 -> 214096.38 | N6: =M6 -> 214096.38 | O6: =Settings!$B$8 -> 176 | P6: Ishlab chiqarish | Q6: =N6/Settings!$B$4 -> 16.661197 | R6: =Q6*O6 -> 2932.3707
A7: 📐 ARXITEKTURA
A8: 3 | B8: Aliyev Sardor | C8: Bosh arxitektor | D8: Arxitektura | E8: 25000000 | F8: 5000000 | G8: =(E8+F8)*0.12 -> 3600000 | H8: =(E8+F8)*0.12 -> 3600000 | I8: =E8+F8+G8+H8 -> 37200000 | J8: =I$34/15/Settings!$B$8 -> 58946.97 | K8: ='Texnika va Overhead'!F15/15 -> 3672.138 | L8: ='Texnika va Overhead'!D39 -> 0 | M8: =I8/Settings!$B$8+J8+K8+L8 -> 273982.74 | N8: =M8 -> 273982.74 | O8: =Settings!$B$8 -> 176 | P8: Ishlab chiqarish | Q8: =N8/Settings!$B$4 -> 21.321614 | R8: =Q8*O8 -> 3752.6041
A9: 4 | B9: Karimov Davron | C9: Katta arxitektor | D9: Arxitektura | E9: 20000000 | F9: 4000000 | G9: =(E9+F9)*0.12 -> 2880000 | H9: =(E9+F9)*0.12 -> 2880000 | I9: =E9+F9+G9+H9 -> 29760000 | J9: =I$34/15/Settings!$B$8 -> 58946.97 | K9: ='Texnika va Overhead'!F15/15 -> 3672.138 | L9: ='Texnika va Overhead'!D39 -> 0 | M9: =I9/Settings!$B$8+J9+K9+L9 -> 231710.02 | N9: =M9 -> 231710.02 | O9: =Settings!$B$8 -> 176 | P9: Ishlab chiqarish | Q9: =N9/Settings!$B$4 -> 18.031908 | R9: =Q9*O9 -> 3173.6158
A10: 5 | B10: Toshmatov Bekzod | C10: Arxitektor | D10: Arxitektura | E10: 15000000 | F10: 3000000 | G10: =(E10+F10)*0.12 -> 2160000 | H10: =(E10+F10)*0.12 -> 2160000 | I10: =E10+F10+G10+H10 -> 22320000 | J10: =I$34/15/Settings!$B$8 -> 58946.97 | K10: ='Texnika va Overhead'!F15/15 -> 3672.138 | L10: ='Texnika va Overhead'!D39 -> 0 | M10: =I10/Settings!$B$8+J10+K10+L10 -> 189437.29 | N10: =M10 -> 189437.29 | O10: =Settings!$B$8 -> 176 | P10: Ishlab chiqarish | Q10: =N10/Settings!$B$4 -> 14.742202 | R10: =Q10*O10 -> 2594.6275
A11: 6 | B11: Ismoilov Farhod | C11: Arxitektor | D11: Arxitektura | E11: 14000000 | F11: 2500000 | G11: =(E11+F11)*0.12 -> 1980000 | H11: =(E11+F11)*0.12 -> 1980000 | I11: =E11+F11+G11+H11 -> 20460000 | J11: =I$34/15/Settings!$B$8 -> 58946.97 | K11: ='Texnika va Overhead'!F15/15 -> 3672.138 | L11: ='Texnika va Overhead'!D39 -> 0 | M11: =I11/Settings!$B$8+J11+K11+L11 -> 178869.11 | N11: =M11 -> 178869.11 | O11: =Settings!$B$8 -> 176 | P11: Ishlab chiqarish | Q11: =N11/Settings!$B$4 -> 13.919775 | R11: =Q11*O11 -> 2449.8804
A12: 🎨 3D VIZUALIZATSIYA
A13: 7 | B13: Abdullayev Otabek | C13: 3D Lead | D13: 3D Vizualizatsiya | E13: 16000000 | F13: 3000000 | G13: =(E13+F13)*0.12 -> 2280000 | H13: =(E13+F13)*0.12 -> 2280000 | I13: =E13+F13+G13+H13 -> 23560000 | J13: =I$34/15/Settings!$B$8 -> 58946.97 | K13: ='Texnika va Overhead'!F15/15 -> 3672.138 | L13: ='Texnika va Overhead'!D39 -> 0 | M13: =I13/Settings!$B$8+J13+K13+L13 -> 196482.74 | N13: =M13 -> 196482.74 | O13: =Settings!$B$8 -> 176 | P13: Ishlab chiqarish | Q13: =N13/Settings!$B$4 -> 15.290486 | R13: =Q13*O13 -> 2691.1255
A14: 8 | B14: Qosimova Nodira | C14: 3D Artist | D14: 3D Vizualizatsiya | E14: 15000000 | F14: 2500000 | G14: =(E14+F14)*0.12 -> 2100000 | H14: =(E14+F14)*0.12 -> 2100000 | I14: =E14+F14+G14+H14 -> 21700000 | J14: =I$34/15/Settings!$B$8 -> 58946.97 | K14: ='Texnika va Overhead'!F15/15 -> 3672.138 | L14: ='Texnika va Overhead'!D39 -> 0 | M14: =I14/Settings!$B$8+J14+K14+L14 -> 185914.56 | N14: =M14 -> 185914.56 | O14: =Settings!$B$8 -> 176 | P14: Ishlab chiqarish | Q14: =N14/Settings!$B$4 -> 14.468059 | R14: =Q14*O14 -> 2546.3784
A15: 🛋️ INTERIOR DESIGN
A16: 9 | B16: Nurmatova Dilnoza | C16: Interior boshlig'i | D16: Interior Design | E16: 16000000 | F16: 3000000 | G16: =(E16+F16)*0.12 -> 2280000 | H16: =(E16+F16)*0.12 -> 2280000 | I16: =E16+F16+G16+H16 -> 23560000 | J16: =I$34/15/Settings!$B$8 -> 58946.97 | K16: ='Texnika va Overhead'!F15/15 -> 3672.138 | L16: ='Texnika va Overhead'!D39 -> 0 | M16: =I16/Settings!$B$8+J16+K16+L16 -> 196482.74 | N16: =M16 -> 196482.74 | O16: =Settings!$B$8 -> 176 | P16: Ishlab chiqarish | Q16: =N16/Settings!$B$4 -> 15.290486 | R16: =Q16*O16 -> 2691.1255
A17: 10 | B17: Ergasheva Shahlo | C17: Interior dizayner | D17: Interior Design | E17: 13000000 | F17: 2000000 | G17: =(E17+F17)*0.12 -> 1800000 | H17: =(E17+F17)*0.12 -> 1800000 | I17: =E17+F17+G17+H17 -> 18600000 | J17: =I$34/15/Settings!$B$8 -> 58946.97 | K17: ='Texnika va Overhead'!F15/15 -> 3672.138 | L17: ='Texnika va Overhead'!D39 -> 0 | M17: =I17/Settings!$B$8+J17+K17+L17 -> 168300.93 | N17: =M17 -> 168300.93 | O17: =Settings!$B$8 -> 176 | P17: Ishlab chiqarish | Q17: =N17/Settings!$B$4 -> 13.097348 | R17: =Q17*O17 -> 2305.1333
A18: 🖼️ GRAPHIC DESIGN
A19: 11 | B19: Mirzayeva Gulnora | C19: Graphic Lead | D19: Graphic Design | E19: 14000000 | F19: 2500000 | G19: =(E19+F19)*0.12 -> 1980000 | H19: =(E19+F19)*0.12 -> 1980000 | I19: =E19+F19+G19+H19 -> 20460000 | J19: =I$34/15/Settings!$B$8 -> 58946.97 | K19: ='Texnika va Overhead'!F15/15 -> 3672.138 | L19: ='Texnika va Overhead'!D39 -> 0 | M19: =I19/Settings!$B$8+J19+K19+L19 -> 178869.11 | N19: =M19 -> 178869.11 | O19: =Settings!$B$8 -> 176 | P19: Ishlab chiqarish | Q19: =N19/Settings!$B$4 -> 13.919775 | R19: =Q19*O19 -> 2449.8804
A20: 12 | B20: Xudoyberdiyev Jasur | C20: Graphic dizayner | D20: Graphic Design | E20: 12000000 | F20: 2000000 | G20: =(E20+F20)*0.12 -> 1680000 | H20: =(E20+F20)*0.12 -> 1680000 | I20: =E20+F20+G20+H20 -> 17360000 | J20: =I$34/15/Settings!$B$8 -> 58946.97 | K20: ='Texnika va Overhead'!F15/15 -> 3672.138 | L20: ='Texnika va Overhead'!D39 -> 0 | M20: =I20/Settings!$B$8+J20+K20+L20 -> 161255.47 | N20: =M20 -> 161255.47 | O20: =Settings!$B$8 -> 176 | P20: Ishlab chiqarish | Q20: =N20/Settings!$B$4 -> 12.549064 | R20: =Q20*O20 -> 2208.6353
A21: 💰 SMETA
A22: 13 | B22: Hasanov Timur | C22: Smetachi | D22: Smeta | E22: 16000000 | F22: 2500000 | G22: =(E22+F22)*0.12 -> 2220000 | H22: =(E22+F22)*0.12 -> 2220000 | I22: =E22+F22+G22+H22 -> 22940000 | J22: =I$34/15/Settings!$B$8 -> 58946.97 | K22: ='Texnika va Overhead'!F15/15 -> 3672.138 | L22: ='Texnika va Overhead'!D39 -> 0 | M22: =I22/Settings!$B$8+J22+K22+L22 -> 192960.02 | N22: =M22 -> 192960.02 | O22: =Settings!$B$8 -> 176 | P22: Ishlab chiqarish | Q22: =N22/Settings!$B$4 -> 15.016344 | R22: =Q22*O22 -> 2642.8765
A23: 🔧 KONSTRUKTOR
A24: 14 | B24: Xolmatov Ulugbek | C24: BIM/Konstruktor lead | D24: Konstruktor | E24: 18000000 | F24: 3500000 | G24: =(E24+F24)*0.12 -> 2580000 | H24: =(E24+F24)*0.12 -> 2580000 | I24: =E24+F24+G24+H24 -> 26660000 | J24: =I$34/15/Settings!$B$8 -> 58946.97 | K24: ='Texnika va Overhead'!F15/15 -> 3672.138 | L24: ='Texnika va Overhead'!D39 -> 0 | M24: =I24/Settings!$B$8+J24+K24+L24 -> 214096.38 | N24: =M24 -> 214096.38 | O24: =Settings!$B$8 -> 176 | P24: Ishlab chiqarish | Q24: =N24/Settings!$B$4 -> 16.661197 | R24: =Q24*O24 -> 2932.3707
A25: 15 | B25: Tursunov Sherzod | C25: Konstruktor | D25: Konstruktor | E25: 17000000 | F25: 3000000 | G25: =(E25+F25)*0.12 -> 2400000 | H25: =(E25+F25)*0.12 -> 2400000 | I25: =E25+F25+G25+H25 -> 24800000 | J25: =I$34/15/Settings!$B$8 -> 58946.97 | K25: ='Texnika va Overhead'!F15/15 -> 3672.138 | L25: ='Texnika va Overhead'!D39 -> 0 | M25: =I25/Settings!$B$8+J25+K25+L25 -> 203528.2 | N25: =M25 -> 203528.2 | O25: =Settings!$B$8 -> 176 | P25: Ishlab chiqarish | Q25: =N25/Settings!$B$4 -> 15.83877 | R25: =Q25*O25 -> 2787.6236
A26: 🏢 MA'MURIYAT
A27: 16 | B27: Yusupov Akbar | C27: Direktor | D27: Ma'muriyat | E27: 35000000 | F27: 8000000 | G27: =(E27+F27)*0.12 -> 5160000 | H27: =(E27+F27)*0.12 -> 5160000 | I27: =E27+F27+G27+H27 -> 53320000 | J27: 0 | K27: 0 | L27: 0 | M27: 0 | N27: - | O27: =Settings!$B$8 -> 176 | P27: Ma'muriyat | Q27: - | R27: -
A28: 17 | B28: Sobirova Malika | C28: Buxgalter | D28: Ma'muriyat | E28: 12000000 | F28: 2000000 | G28: =(E28+F28)*0.12 -> 1680000 | H28: =(E28+F28)*0.12 -> 1680000 | I28: =E28+F28+G28+H28 -> 17360000 | J28: 0 | K28: 0 | L28: 0 | M28: 0 | N28: - | O28: =Settings!$B$8 -> 176 | P28: Ma'muriyat | Q28: - | R28: -
A29: 18 | B29: Raximova Shaxlo | C29: Finansist | D29: Ma'muriyat | E29: 14000000 | F29: 2500000 | G29: =(E29+F29)*0.12 -> 1980000 | H29: =(E29+F29)*0.12 -> 1980000 | I29: =E29+F29+G29+H29 -> 20460000 | J29: 0 | K29: 0 | L29: 0 | M29: 0 | N29: - | O29: =Settings!$B$8 -> 176 | P29: Ma'muriyat | Q29: - | R29: -
A30: 19 | B30: Kamolov Rustam | C30: Ofis menejer | D30: Ma'muriyat | E30: 10000000 | F30: 1500000 | G30: =(E30+F30)*0.12 -> 1380000 | H30: =(E30+F30)*0.12 -> 1380000 | I30: =E30+F30+G30+H30 -> 14260000 | J30: 0 | K30: 0 | L30: 0 | M30: 0 | N30: - | O30: =Settings!$B$8 -> 176 | P30: Ma'muriyat | Q30: - | R30: -
A31: 20 | B31: Xasanova Dilfuza | C31: HR manager | D31: Ma'muriyat | E31: 12000000 | F31: 2000000 | G31: =(E31+F31)*0.12 -> 1680000 | H31: =(E31+F31)*0.12 -> 1680000 | I31: =E31+F31+G31+H31 -> 17360000 | J31: 0 | K31: 0 | L31: 0 | M31: 0 | N31: - | O31: =Settings!$B$8 -> 176 | P31: Ma'muriyat | Q31: - | R31: -
A32: 21 | B32: Salimov Nodir | C32: Yurist | D32: Ma'muriyat | E32: 15000000 | F32: 2500000 | G32: =(E32+F32)*0.12 -> 2100000 | H32: =(E32+F32)*0.12 -> 2100000 | I32: =E32+F32+G32+H32 -> 21700000 | J32: 0 | K32: 0 | L32: 0 | M32: 0 | N32: - | O32: =Settings!$B$8 -> 176 | P32: Ma'muriyat | Q32: - | R32: -
A33: 22 | B33: Tojiboyev Anvar | C33: Farrosh/Texnik | D33: Ma'muriyat | E33: 8000000 | F33: 1000000 | G33: =(E33+F33)*0.12 -> 1080000 | H33: =(E33+F33)*0.12 -> 1080000 | I33: =E33+F33+G33+H33 -> 11160000 | J33: 0 | K33: 0 | L33: 0 | M33: 0 | N33: - | O33: =Settings!$B$8 -> 176 | P33: Ma'muriyat | Q33: - | R33: -
B34: JAMI MA'MURIYAT XARAJATI | I34: =I27+I28+I29+I30+I31+I32+I33 -> 155620000
B35: JAMI BARCHA XODIMLAR | I35: =I27+I28+I29+I30+I31+I32+I33+I5+I6+I8+I9+I10+I11+I13+I14+I16+I17+I19+I20+I22+I24+I25 -> 523900000
B36: O'rtacha 1 soat narxi (ishlab chiqarish) | N36: =AVERAGE(N5,N6,N8,N9,N10,N11,N13,N14,N16,N17,N19,N20,N22,N24,N25) -> 202119.11 | Q36: =N36/Settings!$B$4 -> 15.729113 | R36: =Q36*O36 -> 0

Sheet Texnika va Overhead
A1: TEXNIKA AMORTIZATSIYASI VA OVERHEAD
A3: TEXNIKA AMORTIZATSIYASI
A4: No | B4: Jihoz nomi | C4: Umumiy narxi (UZS) | D4: Muddat (oy) | E4: Oylik amort. | F4: Soatlik amort. | G4: Oylik amort. (USD)
A5: 1 | B5: Dell Precision 7780 (x5) | C5: 75000000 | D5: 36 | E5: =C5/D5 -> 2083333.3 | F5: =E5/Settings!$B$8 -> 11837.121 | G5: =E5/Settings!$B$4 -> 162.12711
A6: 2 | B6: MacBook Pro 16 (x3) | C6: 90000000 | D6: 36 | E6: =C6/D6 -> 2500000 | F6: =E6/Settings!$B$8 -> 14204.545 | G6: =E6/Settings!$B$4 -> 194.55253
A7: 3 | B7: HP DesignJet Plotter | C7: 45000000 | D7: 48 | E7: =C7/D7 -> 937500 | F7: =E7/Settings!$B$8 -> 5326.7045 | G7: =E7/Settings!$B$4 -> 72.957198
A8: 4 | B8: Monitor 4K 32" (x10) | C8: 50000000 | D8: 48 | E8: =C8/D8 -> 1041666.7 | F8: =E8/Settings!$B$8 -> 5918.5606 | G8: =E8/Settings!$B$4 -> 81.063554
A9: 5 | B9: 3D Printer Creality | C9: 15000000 | D9: 36 | E9: =C9/D9 -> 416666.67 | F9: =E9/Settings!$B$8 -> 2367.4242 | G9: =E9/Settings!$B$4 -> 32.425422
A10: 6 | B10: Server Dell PowerEdge | C10: 60000000 | D10: 60 | E10: =C10/D10 -> 1000000 | F10: =E10/Settings!$B$8 -> 5681.8182 | G10: =E10/Settings!$B$4 -> 77.821012
A11: 7 | B11: Skaner A0 format | C11: 25000000 | D11: 48 | E11: =C11/D11 -> 520833.33 | F11: =E11/Settings!$B$8 -> 2959.2803 | G11: =E11/Settings!$B$4 -> 40.531777
A12: 8 | B12: Proyektor Epson | C12: 12000000 | D12: 48 | E12: =C12/D12 -> 250000 | F12: =E12/Settings!$B$8 -> 1420.4545 | G12: =E12/Settings!$B$4 -> 19.455253
A13: 9 | B13: Mebellar (stol, stul) | C13: 40000000 | D13: 60 | E13: =C13/D13 -> 666666.67 | F13: =E13/Settings!$B$8 -> 3787.8788 | G13: =E13/Settings!$B$4 -> 51.880674
A14: 10 | B14: UPS / Stabilizator (x5) | C14: 10000000 | D14: 36 | E14: =C14/D14 -> 277777.78 | F14: =E14/Settings!$B$8 -> 1578.2828 | G14: =E14/Settings!$B$4 -> 21.616948
B15: JAMI TEXNIKA | C15: =SUM(C5:C14) -> 422000000 | E15: =SUM(E5:E14) -> 9694444.4 | F15: =SUM(F5:F14) -> 55082.071 | G15: =SUM(G5:G14) -> 754.43147
A17: OYLIK OVERHEAD XARAJATLAR
A18: No | B18: Xarajat turi | C18: Oylik summa (UZS) | D18: Soatlik summa | E18: Oylik (USD)
A19: 1 | B19: Ofis ijarasi | C19: 15000000 | D19: =C19/(15*Settings!$B$8) -> 5681.8182 | E19: =C19/Settings!$B$4 -> 1167.3152
A20: 2 | B20: Ovqat xarajatlari | C20: 8000000 | D20: =C20/(15*Settings!$B$8) -> 3030.303 | E20: =C20/Settings!$B$4 -> 622.56809
A21: 3 | B21: Internet va telefon | C21: 3000000 | D21: =C21/(15*Settings!$B$8) -> 1136.3636 | E21: =C21/Settings!$B$4 -> 233.46304
A22: 4 | B22: Elektr energiya | C22: 2500000 | D22: =C22/(15*Settings!$B$8) -> 946.9697 | E22: =C22/Settings!$B$4 -> 194.55253
A23: 5 | B23: Ofis yigim-terim | C23: 2000000 | D23: =C23/(15*Settings!$B$8) -> 757.57576 | E23: =C23/Settings!$B$4 -> 155.64202
A24: 6 | B24: Marketing va reklama | C24: 5000000 | D24: =C24/(15*Settings!$B$8) -> 1893.9394 | E24: =C24/Settings!$B$4 -> 389.10506
A25: 7 | B25: Buxgalteriya xizmati | C25: 3000000 | D25: =C25/(15*Settings!$B$8) -> 1136.3636 | E25: =C25/Settings!$B$4 -> 233.46304
A26: 8 | B26: Yuridik xizmatlar | C26: 2000000 | D26: =C26/(15*Settings!$B$8) -> 757.57576 | E26: =C26/Settings!$B$4 -> 155.64202
A27: 9 | B27: Tamirlash va texnik xizmat | C27: 4000000 | D27: =C27/(15*Settings!$B$8) -> 1515.1515 | E27: =C27/Settings!$B$4 -> 311.28405
A28: 10 | B28: Boshqa overhead | C28: 3000000 | D28: =C28/(15*Settings!$B$8) -> 1136.3636 | E28: =C28/Settings!$B$4 -> 233.46304
B29: JAMI OVERHEAD | C29: =SUM(C19:C28) -> 47500000 | D29: =SUM(D19:D28) -> 17992.424 | E29: =SUM(E19:E28) -> 3696.4981

Sheet Proekt vaqt va Risk
A1: PROEKT VAQT HISOBI VA MIZAN ULUSHI
A3: No | B3: Proekt nomi | C3: Risk koeff. | D3: Rahimov (Master) | E3: Azimov (Master) | F3: Aliyev (Arxite) | G3: Karimov (Arxite) | H3: Toshmato (Arxite) | I3: Ismoilov (Arxite) | J3: Abdullay (3D Viz) | K3: Qosimova (3D Viz) | L3: Nurmatov (Interi) | M3: Ergashev (Interi) | N3: Mirzayev (Graphi) | O3: Xudoyber (Graphi) | P3: Hasanov (Smeta) | Q3: Xolmatov (Konstr) | R3: Tursunov (Konstr) | S3: Jami soat | T3: MIZAN ulushi (UZS) | U3: MIZAN ulushi (USD)
A4: 1 | B4: Toshkent City Tower | C4: 1.1 | D4: 60 | E4: 160 | F4: 120 | G4: 60 | H4: 80 | I4: 120 | J4: 60 | K4: 24 | L4: 40 | M4: 80 | N4: 24 | O4: 8 | P4: 16 | Q4: 60 | R4: 24 | S4: =SUM(D4:R4) -> 936 | T4: =(D4*'Xodimlar va Soat narxi'!N5+E4*'Xodimlar va Soat narxi'!N6+F4*'Xodimlar va Soat narxi'!N8+G4*'Xodimlar va Soat narxi'!N9+H4*'Xodimlar va Soat narxi'!N10+I4*'Xodimlar va Soat narxi'!N11+J4*'Xodimlar va Soat narxi'!N13+K4*'Xodimlar va Soat narxi'!N14+L4*'Xodimlar va Soat narxi'!N16+M4*'Xodimlar va Soat narxi'!N17+N4*'Xodimlar va Soat narxi'!N19+O4*'Xodimlar va Soat narxi'!N20+P4*'Xodimlar va Soat narxi'!N22+Q4*'Xodimlar va Soat narxi'!N24+R4*'Xodimlar va Soat narxi'!N25)*C4 -> 2.1601613e+08 | U4: =T4/Settings!$B$4 -> 16810.594
A5: 2 | B5: Samarqand Hotel | C5: 1.15 | D5: 60 | E5: 60 | F5: 40 | G5: 24 | H5: 160 | I5: 40 | J5: 24 | K5: 0 | L5: 80 | M5: 60 | N5: 40 | O5: 0 | P5: 8 | Q5: 8 | R5: 60 | S5: =SUM(D5:R5) -> 664 | T5: =(D5*'Xodimlar va Soat narxi'!N5+E5*'Xodimlar va Soat narxi'!N6+F5*'Xodimlar va Soat narxi'!N8+G5*'Xodimlar va Soat narxi'!N9+H5*'Xodimlar va Soat narxi'!N10+I5*'Xodimlar va Soat narxi'!N11+J5*'Xodimlar va Soat narxi'!N13+K5*'Xodimlar va Soat narxi'!N14+L5*'Xodimlar va Soat narxi'!N16+M5*'Xodimlar va Soat narxi'!N17+N5*'Xodimlar va Soat narxi'!N19+O5*'Xodimlar va Soat narxi'!N20+P5*'Xodimlar va Soat narxi'!N22+Q5*'Xodimlar va Soat narxi'!N24+R5*'Xodimlar va Soat narxi'!N25)*C5 -> 1.549442e+08 | U5: =T5/Settings!$B$4 -> 12057.914
A6: 3 | B6: Buxoro Madaniyat Markazi | C6: 1.2 | D6: 60 | E6: 160 | F6: 120 | G6: 120 | H6: 120 | I6: 60 | J6: 0 | K6: 16 | L6: 24 | M6: 16 | N6: 8 | O6: 0 | P6: 16 | Q6: 0 | R6: 60 | S6: =SUM(D6:R6) -> 780 | T6: =(D6*'Xodimlar va Soat narxi'!N5+E6*'Xodimlar va Soat narxi'!N6+F6*'Xodimlar va Soat narxi'!N8+G6*'Xodimlar va Soat narxi'!N9+H6*'Xodimlar va Soat narxi'!N10+I6*'Xodimlar va Soat narxi'!N11+J6*'Xodimlar va Soat narxi'!N13+K6*'Xodimlar va Soat narxi'!N14+L6*'Xodimlar va Soat narxi'!N16+M6*'Xodimlar va Soat narxi'!N17+N6*'Xodimlar va Soat narxi'!N19+O6*'Xodimlar va Soat narxi'!N20+P6*'Xodimlar va Soat narxi'!N22+Q6*'Xodimlar va Soat narxi'!N24+R6*'Xodimlar va Soat narxi'!N25)*C6 -> 2.0431712e+08 | U6: =T6/Settings!$B$4 -> 15900.165
A7: 4 | B7: Chilonzor Turar-joy | C7: 1.3 | D7: 40 | E7: 60 | F7: 24 | G7: 24 | H7: 120 | I7: 60 | J7: 80 | K7: 16 | L7: 80 | M7: 40 | N7: 0 | O7: 0 | P7: 40 | Q7: 16 | R7: 24 | S7: =SUM(D7:R7) -> 624 | T7: =(D7*'Xodimlar va Soat narxi'!N5+E7*'Xodimlar va Soat narxi'!N6+F7*'Xodimlar va Soat narxi'!N8+G7*'Xodimlar va Soat narxi'!N9+H7*'Xodimlar va Soat narxi'!N10+I7*'Xodimlar va Soat narxi'!N11+J7*'Xodimlar va Soat narxi'!N13+K7*'Xodimlar va Soat narxi'!N14+L7*'Xodimlar va Soat narxi'!N16+M7*'Xodimlar va Soat narxi'!N17+N7*'Xodimlar va Soat narxi'!N19+O7*'Xodimlar va Soat narxi'!N20+P7*'Xodimlar va Soat narxi'!N22+Q7*'Xodimlar va Soat narxi'!N24+R7*'Xodimlar va Soat narxi'!N25)*C7 -> 1.6308707e+08 | U7: =T7/Settings!$B$4 -> 12691.601
A8: 5 | B8: Nukus Biznes Markazi | C8: 1.2 | D8: 80 | E8: 60 | F8: 40 | G8: 24 | H8: 60 | I8: 80 | J8: 0 | K8: 0 | L8: 40 | M8: 40 | N8: 0 | O8: 24 | P8: 60 | Q8: 60 | R8: 0 | S8: =SUM(D8:R8) -> 568 | T8: =(D8*'Xodimlar va Soat narxi'!N5+E8*'Xodimlar va Soat narxi'!N6+F8*'Xodimlar va Soat narxi'!N8+G8*'Xodimlar va Soat narxi'!N9+H8*'Xodimlar va Soat narxi'!N10+I8*'Xodimlar va Soat narxi'!N11+J8*'Xodimlar va Soat narxi'!N13+K8*'Xodimlar va Soat narxi'!N14+L8*'Xodimlar va Soat narxi'!N16+M8*'Xodimlar va Soat narxi'!N17+N8*'Xodimlar va Soat narxi'!N19+O8*'Xodimlar va Soat narxi'!N20+P8*'Xodimlar va Soat narxi'!N22+Q8*'Xodimlar va Soat narxi'!N24+R8*'Xodimlar va Soat narxi'!N25)*C8 -> 1.41109e+08 | U8: =T8/Settings!$B$4 -> 10981.245
A9: 6 | B9: Fargona Shopping Mall | C9: 1.1 | D9: 40 | E9: 120 | F9: 60 | G9: 24 | H9: 40 | I9: 24 | J9: 60 | K9: 40 | L9: 60 | M9: 60 | N9: 24 | O9: 0 | P9: 40 | Q9: 24 | R9: 24 | S9: =SUM(D9:R9) -> 640 | T9: =(D9*'Xodimlar va Soat narxi'!N5+E9*'Xodimlar va Soat narxi'!N6+F9*'Xodimlar va Soat narxi'!N8+G9*'Xodimlar va Soat narxi'!N9+H9*'Xodimlar va Soat narxi'!N10+I9*'Xodimlar va Soat narxi'!N11+J9*'Xodimlar va Soat narxi'!N13+K9*'Xodimlar va Soat narxi'!N14+L9*'Xodimlar va Soat narxi'!N16+M9*'Xodimlar va Soat narxi'!N17+N9*'Xodimlar va Soat narxi'!N19+O9*'Xodimlar va Soat narxi'!N20+P9*'Xodimlar va Soat narxi'!N22+Q9*'Xodimlar va Soat narxi'!N24+R9*'Xodimlar va Soat narxi'!N25)*C9 -> 1.4579485e+08 | U9: =T9/Settings!$B$4 -> 11345.903
A10: 7 | B10: Toshkent Metro Stansiya | C10: 1.2 | D10: 60 | E10: 120 | F10: 80 | G10: 60 | H10: 120 | I10: 120 | J10: 0 | K10: 60 | L10: 80 | M10: 0 | N10: 0 | O10: 40 | P10: 8 | Q10: 16 | R10: 60 | S10: =SUM(D10:R10) -> 824 | T10: =(D10*'Xodimlar va Soat narxi'!N5+E10*'Xodimlar va Soat narxi'!N6+F10*'Xodimlar va Soat narxi'!N8+G10*'Xodimlar va Soat narxi'!N9+H10*'Xodimlar va Soat narxi'!N10+I10*'Xodimlar va Soat narxi'!N11+J10*'Xodimlar va Soat narxi'!N13+K10*'Xodimlar va Soat narxi'!N14+L10*'Xodimlar va Soat narxi'!N16+M10*'Xodimlar va Soat narxi'!N17+N10*'Xodimlar va Soat narxi'!N19+O10*'Xodimlar va Soat narxi'!N20+P10*'Xodimlar va Soat narxi'!N22+Q10*'Xodimlar va Soat narxi'!N24+R10*'Xodimlar va Soat narxi'!N25)*C10 -> 2.0515468e+08 | U10: =T10/Settings!$B$4 -> 15965.345
A11: 8 | B11: Namangan Klinika | C11: 1 | D11: 40 | E11: 40 | F11: 40 | G11: 120 | H11: 24 | I11: 40 | J11: 0 | K11: 40 | L11: 40 | M11: 80 | N11: 24 | O11: 16 | P11: 16 | Q11: 0 | R11: 8 | S11: =SUM(D11:R11) -> 528 | T11: =(D11*'Xodimlar va Soat narxi'!N5+E11*'Xodimlar va Soat narxi'!N6+F11*'Xodimlar va Soat narxi'!N8+G11*'Xodimlar va Soat narxi'!N9+H11*'Xodimlar va Soat narxi'!N10+I11*'Xodimlar va Soat narxi'!N11+J11*'Xodimlar va Soat narxi'!N13+K11*'Xodimlar va Soat narxi'!N14+L11*'Xodimlar va Soat narxi'!N16+M11*'Xodimlar va Soat narxi'!N17+N11*'Xodimlar va Soat narxi'!N19+O11*'Xodimlar va Soat narxi'!N20+P11*'Xodimlar va Soat narxi'!N22+Q11*'Xodimlar va Soat narxi'!N24+R11*'Xodimlar va Soat narxi'!N25)*C11 -> 1.0921016e+08 | U11: =T11/Settings!$B$4 -> 8498.8453
A12: 9 | B12: Andijon Sport Majmuasi | C12: 1.15 | D12: 160 | E12: 60 | F12: 160 | G12: 80 | H12: 24 | I12: 160 | J12: 16 | K12: 24 | L12: 80 | M12: 60 | N12: 40 | O12: 0 | P12: 24 | Q12: 0 | R12: 40 | S12: =SUM(D12:R12) -> 928 | T12: =(D12*'Xodimlar va Soat narxi'!N5+E12*'Xodimlar va Soat narxi'!N6+F12*'Xodimlar va Soat narxi'!N8+G12*'Xodimlar va Soat narxi'!N9+H12*'Xodimlar va Soat narxi'!N10+I12*'Xodimlar va Soat narxi'!N11+J12*'Xodimlar va Soat narxi'!N13+K12*'Xodimlar va Soat narxi'!N14+L12*'Xodimlar va Soat narxi'!N16+M12*'Xodimlar va Soat narxi'!N17+N12*'Xodimlar va Soat narxi'!N19+O12*'Xodimlar va Soat narxi'!N20+P12*'Xodimlar va Soat narxi'!N22+Q12*'Xodimlar va Soat narxi'!N24+R12*'Xodimlar va Soat narxi'!N25)*C12 -> 2.3122223e+08 | U12: =T12/Settings!$B$4 -> 17993.948
